[2025-10-06T07:59:51.665+0000] {taskinstance.py:1956} INFO - Dependencies all met for dep_context=non-requeueable deps ti=<TaskInstance: inventory_analytics_pipeline.create_inventory_table manual__2025-10-06T07:54:29.292935+00:00 [queued]>
[2025-10-06T07:59:51.947+0000] {taskinstance.py:1956} INFO - Dependencies all met for dep_context=requeueable deps ti=<TaskInstance: inventory_analytics_pipeline.create_inventory_table manual__2025-10-06T07:54:29.292935+00:00 [queued]>
[2025-10-06T07:59:52.001+0000] {taskinstance.py:2170} INFO - Starting attempt 2 of 2
[2025-10-06T07:59:52.249+0000] {taskinstance.py:2191} INFO - Executing <Task(PythonOperator): create_inventory_table> on 2025-10-06 07:54:29.292935+00:00
[2025-10-06T07:59:52.470+0000] {standard_task_runner.py:60} INFO - Started process 343 to run task
[2025-10-06T07:59:52.797+0000] {standard_task_runner.py:87} INFO - Running: ['***', 'tasks', 'run', 'inventory_analytics_pipeline', 'create_inventory_table', 'manual__2025-10-06T07:54:29.292935+00:00', '--job-id', '7', '--raw', '--subdir', 'DAGS_FOLDER/inventory_analytics_pipeline.py', '--cfg-path', '/tmp/tmpd1bp8m5u']
[2025-10-06T07:59:52.942+0000] {standard_task_runner.py:88} INFO - Job 7: Subtask create_inventory_table
[2025-10-06T07:59:53.859+0000] {logging_mixin.py:188} WARNING - /home/***/.local/lib/python3.8/site-packages/***/settings.py:194 DeprecationWarning: The sql_alchemy_conn option in [core] has been moved to the sql_alchemy_conn option in [database] - the old setting has been used, but please update your config.
[2025-10-06T07:59:57.453+0000] {task_command.py:423} INFO - Running <TaskInstance: inventory_analytics_pipeline.create_inventory_table manual__2025-10-06T07:54:29.292935+00:00 [running]> on host ea4788e59d79
[2025-10-06T07:59:59.561+0000] {taskinstance.py:2480} INFO - Exporting env vars: AIRFLOW_CTX_DAG_OWNER='***' AIRFLOW_CTX_DAG_ID='inventory_analytics_pipeline' AIRFLOW_CTX_TASK_ID='create_inventory_table' AIRFLOW_CTX_EXECUTION_DATE='2025-10-06T07:54:29.292935+00:00' AIRFLOW_CTX_TRY_NUMBER='2' AIRFLOW_CTX_DAG_RUN_ID='manual__2025-10-06T07:54:29.292935+00:00'
[2025-10-06T07:59:59.641+0000] {base.py:83} INFO - Using connection ID 'postgres_default' for task execution.
[2025-10-06T07:59:59.658+0000] {taskinstance.py:2698} ERROR - Task failed with exception
Traceback (most recent call last):
  File "/home/airflow/.local/lib/python3.8/site-packages/airflow/models/taskinstance.py", line 433, in _execute_task
    result = execute_callable(context=context, **execute_callable_kwargs)
  File "/home/airflow/.local/lib/python3.8/site-packages/airflow/operators/python.py", line 199, in execute
    return_value = self.execute_callable()
  File "/home/airflow/.local/lib/python3.8/site-packages/airflow/operators/python.py", line 216, in execute_callable
    return self.python_callable(*self.op_args, **self.op_kwargs)
  File "/opt/airflow/dags/inventory_analytics_pipeline.py", line 30, in create_inventory_table
    hook.run(create_table_sql)
  File "/home/airflow/.local/lib/python3.8/site-packages/airflow/providers/common/sql/hooks/sql.py", line 391, in run
    with closing(self.get_conn()) as conn:
  File "/home/airflow/.local/lib/python3.8/site-packages/airflow/providers/postgres/hooks/postgres.py", line 158, in get_conn
    self.conn = psycopg2.connect(**conn_args)
  File "/home/airflow/.local/lib/python3.8/site-packages/psycopg2/__init__.py", line 122, in connect
    conn = _connect(dsn, connection_factory=connection_factory, **kwasync)
psycopg2.OperationalError: connection to server at "postgres" (172.24.0.2), port 5432 failed: FATAL:  password authentication failed for user "postgres"

[2025-10-06T07:59:59.724+0000] {taskinstance.py:1138} INFO - Marking task as FAILED. dag_id=inventory_analytics_pipeline, task_id=create_inventory_table, execution_date=20251006T075429, start_date=20251006T075951, end_date=20251006T075959
[2025-10-06T07:59:59.763+0000] {standard_task_runner.py:107} ERROR - Failed to execute job 7 for task create_inventory_table (connection to server at "postgres" (172.24.0.2), port 5432 failed: FATAL:  password authentication failed for user "postgres"
; 343)
[2025-10-06T07:59:59.821+0000] {local_task_job_runner.py:234} INFO - Task exited with return code 1
[2025-10-06T07:59:59.910+0000] {taskinstance.py:3280} INFO - 0 downstream tasks scheduled from follow-on schedule check
