[2025-10-06T08:03:09.703+0000] {taskinstance.py:1956} INFO - Dependencies all met for dep_context=non-requeueable deps ti=<TaskInstance: inventory_analytics_pipeline.create_inventory_table manual__2025-10-06T08:02:59.093110+00:00 [queued]>
[2025-10-06T08:03:09.749+0000] {taskinstance.py:1956} INFO - Dependencies all met for dep_context=requeueable deps ti=<TaskInstance: inventory_analytics_pipeline.create_inventory_table manual__2025-10-06T08:02:59.093110+00:00 [queued]>
[2025-10-06T08:03:09.750+0000] {taskinstance.py:2170} INFO - Starting attempt 1 of 2
[2025-10-06T08:03:10.056+0000] {taskinstance.py:2191} INFO - Executing <Task(PythonOperator): create_inventory_table> on 2025-10-06 08:02:59.093110+00:00
[2025-10-06T08:03:10.132+0000] {standard_task_runner.py:60} INFO - Started process 382 to run task
[2025-10-06T08:03:10.228+0000] {standard_task_runner.py:87} INFO - Running: ['***', 'tasks', 'run', 'inventory_analytics_pipeline', 'create_inventory_table', 'manual__2025-10-06T08:02:59.093110+00:00', '--job-id', '8', '--raw', '--subdir', 'DAGS_FOLDER/inventory_analytics_pipeline.py', '--cfg-path', '/tmp/tmp_t46e38w']
[2025-10-06T08:03:10.243+0000] {standard_task_runner.py:88} INFO - Job 8: Subtask create_inventory_table
[2025-10-06T08:03:10.384+0000] {logging_mixin.py:188} WARNING - /home/***/.local/lib/python3.8/site-packages/***/settings.py:194 DeprecationWarning: The sql_alchemy_conn option in [core] has been moved to the sql_alchemy_conn option in [database] - the old setting has been used, but please update your config.
[2025-10-06T08:03:10.577+0000] {task_command.py:423} INFO - Running <TaskInstance: inventory_analytics_pipeline.create_inventory_table manual__2025-10-06T08:02:59.093110+00:00 [running]> on host ea4788e59d79
[2025-10-06T08:03:11.016+0000] {taskinstance.py:2480} INFO - Exporting env vars: AIRFLOW_CTX_DAG_OWNER='***' AIRFLOW_CTX_DAG_ID='inventory_analytics_pipeline' AIRFLOW_CTX_TASK_ID='create_inventory_table' AIRFLOW_CTX_EXECUTION_DATE='2025-10-06T08:02:59.093110+00:00' AIRFLOW_CTX_TRY_NUMBER='1' AIRFLOW_CTX_DAG_RUN_ID='manual__2025-10-06T08:02:59.093110+00:00'
[2025-10-06T08:03:11.446+0000] {base.py:83} INFO - Using connection ID 'postgres_default' for task execution.
[2025-10-06T08:03:11.508+0000] {taskinstance.py:2698} ERROR - Task failed with exception
Traceback (most recent call last):
  File "/home/airflow/.local/lib/python3.8/site-packages/airflow/models/taskinstance.py", line 433, in _execute_task
    result = execute_callable(context=context, **execute_callable_kwargs)
  File "/home/airflow/.local/lib/python3.8/site-packages/airflow/operators/python.py", line 199, in execute
    return_value = self.execute_callable()
  File "/home/airflow/.local/lib/python3.8/site-packages/airflow/operators/python.py", line 216, in execute_callable
    return self.python_callable(*self.op_args, **self.op_kwargs)
  File "/opt/airflow/dags/inventory_analytics_pipeline.py", line 30, in create_inventory_table
    hook.run(create_table_sql)
  File "/home/airflow/.local/lib/python3.8/site-packages/airflow/providers/common/sql/hooks/sql.py", line 391, in run
    with closing(self.get_conn()) as conn:
  File "/home/airflow/.local/lib/python3.8/site-packages/airflow/providers/postgres/hooks/postgres.py", line 158, in get_conn
    self.conn = psycopg2.connect(**conn_args)
  File "/home/airflow/.local/lib/python3.8/site-packages/psycopg2/__init__.py", line 122, in connect
    conn = _connect(dsn, connection_factory=connection_factory, **kwasync)
psycopg2.OperationalError: connection to server at "postgres" (172.24.0.2), port 5435 failed: Connection refused
	Is the server running on that host and accepting TCP/IP connections?

[2025-10-06T08:03:11.740+0000] {taskinstance.py:1138} INFO - Marking task as UP_FOR_RETRY. dag_id=inventory_analytics_pipeline, task_id=create_inventory_table, execution_date=20251006T080259, start_date=20251006T080309, end_date=20251006T080311
[2025-10-06T08:03:11.820+0000] {standard_task_runner.py:107} ERROR - Failed to execute job 8 for task create_inventory_table (connection to server at "postgres" (172.24.0.2), port 5435 failed: Connection refused
	Is the server running on that host and accepting TCP/IP connections?
; 382)
[2025-10-06T08:03:11.978+0000] {local_task_job_runner.py:234} INFO - Task exited with return code 1
[2025-10-06T08:03:12.208+0000] {taskinstance.py:3280} INFO - 0 downstream tasks scheduled from follow-on schedule check
